[2024-05-05T14:35:50.400+0000] {task_context_logger.py:104} ERROR - Executor reports task instance <TaskInstance: dog_api.get_dog_api scheduled__2024-05-04T00:00:00+00:00 [queued]> finished (failed) although the task says it's queued. (Info: None) Was the task killed externally?
